<?xml version="1.0" encoding="utf-8"?>

<robot name="x20Z1_description">
  <material name="black">
    <color rgba="0.0 0.0 0.0 1.0" />
  </material>
  <material name="blue">
    <color rgba="0.0 0.0 0.8 1.0" />
  </material>
  <material name="green">
    <color rgba="0.0 0.8 0.0 1.0" />
  </material>
  <material name="grey">
    <color rgba="0.2 0.2 0.2 1.0" />
  </material>
  <material name="silver">
    <color rgba="0.9137254901960784 0.9137254901960784 0.8470588235294118 1.0" />
  </material>
  <material name="orange">
    <color rgba="1.0 0.4235294117647059 0.0392156862745098 1.0" />
  </material>
  <material name="brown">
    <color rgba="0.8705882352941177 0.8117647058823529 0.7647058823529411 1.0" />
  </material>
  <material name="red">
    <color rgba="0.8 0.0 0.0 1.0" />
  </material>
  <material name="white">
    <color rgba="1.0 1.0 1.0 1.0" />
  </material>
  <gazebo>
    <plugin filename="libgazebo_ros_control.so" name="gazebo_ros_control">
      <robotNamespace>/x20Z1_gazebo</robotNamespace>
      <robotSimType>gazebo_ros_control/DefaultRobotHWSim</robotSimType>
    </plugin>
  </gazebo>
  <!-- Show the trajectory of trunk center. -->
  <gazebo>
    <plugin filename="libLinkPlot3DPlugin.so" name="3dplot">
      <frequency>10</frequency>
      <plot>
        <link>base</link>
        <pose>0 0 0 0 0 0</pose>
        <material>Gazebo/Yellow</material>
      </plot>
    </plugin>
  </gazebo>
  <gazebo>
    <plugin filename="libgazebo_ros_force.so" name="gazebo_ros_force">
      <bodyName>trunk</bodyName>
      <topicName>/apply_force/trunk</topicName>
    </plugin>
  </gazebo>
  <gazebo reference="imu_link">
    <gravity>true</gravity>
    <sensor name="imu_sensor" type="imu">
      <always_on>true</always_on>
      <update_rate>1000</update_rate>
      <visualize>true</visualize>
      <topic>__default_topic__</topic>
      <plugin filename="libgazebo_ros_imu_sensor.so" name="imu_plugin">
        <topicName>trunk_imu</topicName>
        <bodyName>imu_link</bodyName>
        <updateRateHZ>1000.0</updateRateHZ>
        <gaussianNoise>0.0</gaussianNoise>
        <xyzOffset>0 0 0</xyzOffset>
        <rpyOffset>0 0 0</rpyOffset>
        <frameName>imu_link</frameName>
      </plugin>
      <pose>0 0 0 0 0 0</pose>
    </sensor>
  </gazebo>
  <!-- Foot contacts. -->
  <gazebo reference="FL_calf">
    <sensor name="FL_foot_contact" type="contact">
      <update_rate>100</update_rate>
      <plugin filename="libunitreeFootContactPlugin.so" name="contactPlugin" />
      <contact>
        <collision>FL_foot_collision_1</collision>
      </contact>
    </sensor>
  </gazebo>
  <gazebo reference="FR_calf">
    <sensor name="FR_foot_contact" type="contact">
      <update_rate>100</update_rate>
      <plugin filename="libunitreeFootContactPlugin.so" name="contactPlugin" />
      <contact>
        <collision>FR_foot_collision_1</collision>
      </contact>
    </sensor>
  </gazebo>
  <gazebo reference="RL_calf">
    <sensor name="RL_foot_contact" type="contact">
      <update_rate>100</update_rate>
      <plugin filename="libunitreeFootContactPlugin.so" name="contactPlugin" />
      <contact>
        <collision>RL_foot_collision_1</collision>
      </contact>
    </sensor>
  </gazebo>
  <gazebo reference="RR_calf">
    <sensor name="RR_foot_contact" type="contact">
      <update_rate>100</update_rate>
      <plugin filename="libunitreeFootContactPlugin.so" name="contactPlugin" />
      <contact>
        <collision>RR_foot_collision_1</collision>
      </contact>
    </sensor>
  </gazebo>
  <!-- Visualization of Foot contacts. -->
  <gazebo reference="FL_foot">
    <visual>
      <plugin filename="libunitreeDrawForcePlugin.so" name="drawForcePlugin">
        <topicName>FL_foot_contact</topicName>
      </plugin>
    </visual>
  </gazebo>
  <gazebo reference="FR_foot">
    <visual>
      <plugin filename="libunitreeDrawForcePlugin.so" name="drawForcePlugin">
        <topicName>FR_foot_contact</topicName>
      </plugin>
    </visual>
  </gazebo>
  <gazebo reference="RL_foot">
    <visual>
      <plugin filename="libunitreeDrawForcePlugin.so" name="drawForcePlugin">
        <topicName>RL_foot_contact</topicName>
      </plugin>
    </visual>
  </gazebo>
  <gazebo reference="RR_foot">
    <visual>
      <plugin filename="libunitreeDrawForcePlugin.so" name="drawForcePlugin">
        <topicName>RR_foot_contact</topicName>
      </plugin>
    </visual>
  </gazebo>
  <gazebo reference="base">
    <material>Gazebo/Green</material>
    <turnGravityOff>false</turnGravityOff>
  </gazebo>
  <gazebo reference="trunk">
    <mu1>0.2</mu1>
    <mu2>0.2</mu2>
    <kp value="1000000.0" />
    <kd value="1.0" />
  </gazebo>
  <gazebo reference="stick_link">
    <mu1>0.2</mu1>
    <mu2>0.2</mu2>
    <material>Gazebo/White</material>
  </gazebo>
  <gazebo reference="imu_link">
    <mu1>0.2</mu1>
    <mu2>0.2</mu2>
    <material>Gazebo/Red</material>
  </gazebo>
  <gazebo reference="FL_hip">
    <mu1>0.2</mu1>
    <mu2>0.2</mu2>
  </gazebo>
  <gazebo reference="FL_thigh">
    <mu1>0.2</mu1>
    <mu2>0.2</mu2>
    <self_collide>1</self_collide>
    <kp value="1000000.0" />
    <kd value="1.0" />
  </gazebo>
  <gazebo reference="FL_calf">
    <mu1>0.2</mu1>
    <mu2>0.2</mu2>
    <self_collide>1</self_collide>
  </gazebo>
  <gazebo reference="FL_foot">
    <mu1>0.6</mu1>
    <mu2>0.6</mu2>
    <self_collide>1</self_collide>
    <kp value="1000000.0" />
    <kd value="1.0" />
  </gazebo>
  <gazebo reference="FR_hip">
    <mu1>0.2</mu1>
    <mu2>0.2</mu2>
  </gazebo>
  <gazebo reference="FR_thigh">
    <mu1>0.2</mu1>
    <mu2>0.2</mu2>
    <self_collide>1</self_collide>
    <kp value="1000000.0" />
    <kd value="1.0" />
  </gazebo>
  <gazebo reference="FR_calf">
    <mu1>0.2</mu1>
    <mu2>0.2</mu2>
    <self_collide>1</self_collide>
  </gazebo>
  <gazebo reference="FR_foot">
    <mu1>0.6</mu1>
    <mu2>0.6</mu2>
    <self_collide>1</self_collide>
    <kp value="1000000.0" />
    <kd value="1.0" />
  </gazebo>
  <gazebo reference="RL_hip">
    <mu1>0.2</mu1>
    <mu2>0.2</mu2>
  </gazebo>
  <gazebo reference="RL_thigh">
    <mu1>0.2</mu1>
    <mu2>0.2</mu2>
    <self_collide>1</self_collide>
    <kp value="1000000.0" />
    <kd value="1.0" />
  </gazebo>
  <gazebo reference="RL_calf">
    <mu1>0.2</mu1>
    <mu2>0.2</mu2>
    <self_collide>1</self_collide>
  </gazebo>
  <gazebo reference="RL_foot">
    <mu1>0.6</mu1>
    <mu2>0.6</mu2>
    <self_collide>1</self_collide>
    <kp value="1000000.0" />
    <kd value="1.0" />
  </gazebo>
  <gazebo reference="RR_hip">
    <mu1>0.2</mu1>
    <mu2>0.2</mu2>
  </gazebo>
  <gazebo reference="RR_thigh">
    <mu1>0.2</mu1>
    <mu2>0.2</mu2>
    <self_collide>1</self_collide>
    <kp value="1000000.0" />
    <kd value="1.0" />
  </gazebo>
  <gazebo reference="RR_calf">
    <mu1>0.2</mu1>
    <mu2>0.2</mu2>
    <self_collide>1</self_collide>
  </gazebo>
  <gazebo reference="RR_foot">
    <mu1>0.6</mu1>
    <mu2>0.6</mu2>
    <self_collide>1</self_collide>
    <kp value="1000000.0" />
    <kd value="1.0" />
  </gazebo>

  <!-- <link name="world"/>
  <joint name="world_joint" type="fixed">
    <parent link="world"/>
    <child link="base"/>
    <origin xyz="0 0 0" rpy="0 0 0"/>
  </joint> -->

  <link name="base">
    <visual>
      <origin rpy="0 0 0" xyz="0 0 0" />
      <geometry>
        <box size="0.001 0.001 0.001" />
      </geometry>
    </visual>
    <inertial>
      <mass value="0.0001" />
      <inertia ixx="1E-12" ixy="0" ixz="0" iyy="1E-12" iyz="0" izz="1E-12" />
    </inertial>
    <collision>
      <geometry>
        <box size="0.46 0.26 0.15" />
      </geometry>
    </collision>
  </link>
  <joint name="floating_base" type="fixed">
    <parent link="base" />
    <child link="trunk" />
  </joint>
  <link name="trunk">
    <inertial>
      <origin xyz="0.0049299 0.00041299 0.0040884" />
      <mass value="26.398" />
      <inertia ixx="0.313256" ixy="-5.2136E-05" ixz="-0.00019406" iyy="0.51388" iyz="8.2679E-05" izz="0.651151" />
    </inertial>
    <visual>
      <geometry>
        <mesh filename="package://x20Z1_description/meshes/visual/Torso.dae" scale="1 1 1" />
      </geometry>
    </visual>
  </link>
  <joint name="imu_joint" type="fixed">
    <parent link="base" />
    <child link="imu_link" />
    <origin rpy="0 0 0" xyz="0 0 0" />
  </joint>
  <link name="imu_link">
    <inertial>
      <mass value="0.001" />
      <origin rpy="0 0 0" xyz="0 0 0" />
      <inertia ixx="0.0001" ixy="0" ixz="0" iyy="0.0001" iyz="0" izz="0.0001" />
    </inertial>
    <visual>
      <origin rpy="0 0 0" xyz="0 0 0" />
      <geometry>
        <box size="0.001 0.001 0.001" />
      </geometry>
      <material name="red" />
    </visual>
    <!-- <collision>
          <origin rpy="0 0 0" xyz="0 0 0"/>
          <geometry>
              <box size=".001 .001 .001"/>
          </geometry>
      </collision> -->
  </link> --&gt; <joint name="trunk_arm_joint" type="fixed">
  <origin rpy="0 0 0" xyz="0.265 0 0.085" />
  <parent link="trunk" />
  <child link="link00" />
</joint>
<link name="link00">
  <visual>
    <origin rpy="0 0 0" xyz="0 0 0" />
    <geometry>
      <mesh filename="package://x20Z1_description/meshes/visual/z1_Link00.dae" scale="1 1 1" />
    </geometry>
  </visual>
  <collision>
    <geometry>
      <cylinder length="0.051" radius="0.0325" />
    </geometry>
    <origin rpy="0 0 0" xyz="0 0 0.0255" />
  </collision>
  <inertial>
    <origin rpy="0 0 0" xyz="-0.00334984 -0.00013615 0.02495843" />
    <mass value="0.47247481" />
    <inertia ixx="0.00037937" ixy="-3.5e-07" ixz="-1.037e-05" iyy="0.00041521" iyz="-9.9e-07" izz="0.00053066" />
  </inertial>
</link>
<joint name="joint1" type="revolute">
  <origin rpy="0 0 0" xyz="0 0 0.0585" />
  <parent link="link00" />
  <child link="link01" />
  <axis xyz="0 0 1" />
  <dynamics damping="1.0" friction="1.0" />
  <limit effort="30.0" lower="-2.6179938779914944" upper="2.6179938779914944" velocity="3.1415" />
</joint>
<link name="link01">
  <visual>
    <origin rpy="0 0 0" xyz="0 0 0" />
    <geometry>
      <mesh filename="package://x20Z1_description/meshes/visual/z1_Link01.dae" scale="1 1 1" />
    </geometry>
  </visual>
  <collision>
    <geometry>
      <cylinder length="0.102" radius="0.0325" />
    </geometry>
    <origin rpy="0 0 0" xyz="0 0 0" />
  </collision>
  <inertial>
    <origin rpy="0 0 0" xyz="2.47e-06 -0.00025198 0.02317169" />
    <mass value="0.67332551" />
    <inertia ixx="0.00128328" ixy="-6e-08" ixz="-4e-07" iyy="0.00071931" iyz="5e-07" izz="0.00083936" />
  </inertial>
</link>
<joint name="joint2" type="revolute">
  <origin rpy="0 0 0" xyz="0 0 0.045" />
  <parent link="link01" />
  <child link="link02" />
  <axis xyz="0 1 0" />
  <dynamics damping="2.0" friction="2.0" />
  <limit effort="60.0" lower="0.0" upper="2.9670597283903604" velocity="3.1415" />
</joint>
<link name="link02">
  <visual>
    <origin rpy="0 0 0" xyz="0 0 0" />
    <geometry>
      <mesh filename="package://x20Z1_description/meshes/visual/z1_Link02.dae" scale="1 1 1" />
    </geometry>
  </visual>
  <collision>
    <geometry>
      <cylinder length="0.102" radius="0.0325" />
    </geometry>
    <origin rpy="1.5707963267948966 0 0" xyz="0 0 0" />
  </collision>
  <collision>
    <geometry>
      <cylinder length="0.235" radius="0.0225" />
    </geometry>
    <origin rpy="0 1.5707963267948966 0" xyz="-0.16249999999999998 0 0" />
  </collision>
  <collision>
    <geometry>
      <cylinder length="0.051" radius="0.0325" />
    </geometry>
    <origin rpy="1.5707963267948966 0 0" xyz="-0.35 0 0" />
  </collision>
  <inertial>
    <origin rpy="0 0 0" xyz="-0.11012601 0.00240029 0.00158266" />
    <mass value="1.19132258" />
    <inertia ixx="0.00102138" ixy="0.00062358" ixz="5.13e-06" iyy="0.02429457" iyz="-2.1e-06" izz="0.02466114" />
  </inertial>
</link>
<joint name="joint3" type="revolute">
  <origin rpy="0 0 0" xyz="-0.35 0 0" />
  <parent link="link02" />
  <child link="link03" />
  <axis xyz="0 1 0" />
  <dynamics damping="1.0" friction="1.0" />
  <limit effort="30.0" lower="-2.8797932657906435" upper="0.0" velocity="3.1415" />
</joint>
<link name="link03">
  <visual>
    <origin rpy="0 0 0" xyz="0 0 0" />
    <geometry>
      <mesh filename="package://x20Z1_description/meshes/visual/z1_Link03.dae" scale="1 1 1" />
    </geometry>
  </visual>
  <collision>
    <geometry>
      <cylinder length="0.116" radius="0.02" />
    </geometry>
    <origin rpy="0 1.5707963267948966 0" xyz="0.128 0 0.055" />
  </collision>
  <collision>
    <geometry>
      <cylinder length="0.059" radius="0.0325" />
    </geometry>
    <origin rpy="0 1.5707963267948966 1.5707963267948966" xyz="0.2205 0 0.055" />
  </collision>
  <inertial>
    <origin rpy="0 0 0" xyz="0.10609208 -0.00541815 0.03476383" />
    <mass value="0.83940874" />
    <inertia ixx="0.00108061" ixy="-8.669e-05" ixz="-0.00208102" iyy="0.00954238" iyz="-1.332e-05" izz="0.00886621" />
  </inertial>
</link>
<joint name="joint4" type="revolute">
  <origin rpy="0 0 0" xyz="0.218 0 0.057" />
  <parent link="link03" />
  <child link="link04" />
  <axis xyz="0 1 0" />
  <dynamics damping="1.0" friction="1.0" />
  <limit effort="30.0" lower="-1.5184364492350666" upper="1.5184364492350666" velocity="3.1415" />
</joint>
<link name="link04">
  <visual>
    <origin rpy="0 0 0" xyz="0 0 0" />
    <geometry>
      <mesh filename="package://x20Z1_description/meshes/visual/z1_Link04.dae" scale="1 1 1" />
    </geometry>
  </visual>
  <collision>
    <geometry>
      <cylinder length="0.067" radius="0.0325" />
    </geometry>
    <origin rpy="0 0 0" xyz="0.072 0 0" />
  </collision>
  <inertial>
    <origin rpy="0 0 0" xyz="0.04366681 0.00364738 -0.00170192" />
    <mass value="0.56404563" />
    <inertia ixx="0.00031576" ixy="8.13e-05" ixz="4.091e-05" iyy="0.00092996" iyz="-5.96e-06" izz="0.00097912" />
  </inertial>
</link>
<joint name="joint5" type="revolute">
  <origin rpy="0 0 0" xyz="0.07 0.0 0.0" />
  <parent link="link04" />
  <child link="link05" />
  <axis xyz="0 0 1" />
  <dynamics damping="1.0" friction="1.0" />
  <limit effort="30.0" lower="-1.3439035240356338" upper="1.3439035240356338" velocity="3.1415" />
</joint>
<link name="link05">
  <visual>
    <origin rpy="0 0 0" xyz="0 0 0" />
    <geometry>
      <mesh filename="package://x20Z1_description/meshes/visual/z1_Link05.dae" scale="1 1 1" />
    </geometry>
  </visual>
  <inertial>
    <origin rpy="0 0 0" xyz="0.03121533 0.0 0.00646316" />
    <mass value="0.38938492" />
    <inertia ixx="0.00017605" ixy="4e-07" ixz="5.689e-05" iyy="0.00055896" iyz="-1.3e-07" izz="0.0005386" />
  </inertial>
</link>
<joint name="joint6" type="revolute">
  <origin rpy="0 0 0" xyz="0.0492 0.0 0.0" />
  <parent link="link05" />
  <child link="link06" />
  <axis xyz="1 0 0" />
  <dynamics damping="1.0" friction="1.0" />
  <limit effort="30.0" lower="-2.792526803190927" upper="2.792526803190927" velocity="3.1415" />
</joint>
<link name="link06">
  <visual>
    <origin rpy="0 0 0" xyz="0 0 0" />
    <geometry>
      <mesh filename="package://x20Z1_description/meshes/visual/z1_Link06.dae" scale="1 1 1" />
    </geometry>
  </visual>
  <collision>
    <geometry>
      <cylinder length="0.051" radius="0.0325" />
    </geometry>
    <origin rpy="0 1.5707963267948966 0" xyz="0.0255 0 0" />
  </collision>
  <inertial>
    <origin rpy="0 0 0" xyz="0.0241569 -0.00017355 -0.00143876" />
    <mass value="0.28875807" />
    <inertia ixx="0.00018328" ixy="1.22e-06" ixz="5.4e-07" iyy="0.0001475" iyz="8e-08" izz="0.0001468" />
  </inertial>
</link>
<joint name="gripperStator" type="fixed">
  <origin rpy="0 0 0" xyz="0.051 0.0 0.0" />
  <parent link="link06" />
  <child link="gripperStator" />
</joint>
<link name="gripperStator">
  <visual>
    <geometry>
      <mesh filename="package://x20Z1_description/meshes/visual/z1_GripperStator.dae" scale="1 1 1" />
    </geometry>
  </visual>
  <collision>
    <geometry>
      <mesh filename="package://x20Z1_description/meshes/collision/z1_GripperStator.obj" scale="1 1 1" />
    </geometry>
  </collision>
  <inertial>
    <origin rpy="0 0 0" xyz="0.04764427 -0.00035819 -0.00249162" />
    <mass value="0.52603655" />
    <inertia ixx="0.00038683" ixy="-3.59e-06" ixz="7.662e-05" iyy="0.00068614" iyz="2.09e-06" izz="0.00066293" />
  </inertial>
</link>
<joint name="jointGripper" type="revolute">
  <origin rpy="0 0 0" xyz="0.049 0.0 0" />
  <parent link="gripperStator" />
  <child link="gripperMover" />
  <axis xyz="0 1 0" />
  <dynamics damping="1.0" friction="1.0" />
  <limit effort="30.0" lower="-1.5707963267948966" upper="0.0" velocity="3.1415" />
</joint>
<link name="gripperMover">
  <visual>
    <geometry>
      <mesh filename="package://x20Z1_description/meshes/visual/z1_GripperMover.dae" scale="1 1 1" />
    </geometry>
  </visual>
  <collision>
    <geometry>
      <mesh filename="package://x20Z1_description/meshes/collision/z1_GripperMover.obj" scale="1 1 1" />
    </geometry>
  </collision>
  <inertial>
    <origin rpy="0 0 0" xyz="0.01320633 0.00476708 0.00380534" />
    <mass value="0.27621302" />
    <inertia ixx="0.00017716" ixy="1.683e-05" ixz="-1.786e-05" iyy="0.00026787" iyz="2.62e-06" izz="0.00035728" />
  </inertial>
</link>
<joint name="endEffector" type="fixed">
  <origin rpy="0 0 0" xyz="0.094 0.0 0" />
  <parent link="gripperStator" />
  <child link="endEffector" />
</joint>
<link name="endEffector">
  <mass value="0.0" />
  <inertia ixx="0.0" ixy="0.0" ixz="0.0" iyy="0.0" iyz="0.0" izz="0.0" />
</link>
<transmission name="JointTransGripper">
  <type>transmission_interface/SimpleTransmission</type>
  <joint name="jointGripper">
    <hardwareInterface>hardware_interface/EffortJointInterface</hardwareInterface>
  </joint>
  <actuator name="ActuatorGripper">
    <hardwareInterface>hardware_interface/EffortJointInterface</hardwareInterface>
    <mechanicalReduction>1</mechanicalReduction>
  </actuator>
</transmission>
<gazebo reference="gripperStator">
  <self_collide>true</self_collide>
</gazebo>
<gazebo reference="gripperMover">
  <self_collide>true</self_collide>
</gazebo>
<transmission name="JointTrans1">
  <type>transmission_interface/SimpleTransmission</type>
  <joint name="joint1">
    <hardwareInterface>hardware_interface/EffortJointInterface</hardwareInterface>
  </joint>
  <actuator name="Actuator1">
    <hardwareInterface>hardware_interface/EffortJointInterface</hardwareInterface>
    <mechanicalReduction>1</mechanicalReduction>
  </actuator>
</transmission>
<transmission name="JointTrans2">
  <type>transmission_interface/SimpleTransmission</type>
  <joint name="joint2">
    <hardwareInterface>hardware_interface/EffortJointInterface</hardwareInterface>
  </joint>
  <actuator name="Actuator2">
    <hardwareInterface>hardware_interface/EffortJointInterface</hardwareInterface>
    <mechanicalReduction>1</mechanicalReduction>
  </actuator>
</transmission>
<transmission name="JointTrans3">
  <type>transmission_interface/SimpleTransmission</type>
  <joint name="joint3">
    <hardwareInterface>hardware_interface/EffortJointInterface</hardwareInterface>
  </joint>
  <actuator name="Actuator3">
    <hardwareInterface>hardware_interface/EffortJointInterface</hardwareInterface>
    <mechanicalReduction>1</mechanicalReduction>
  </actuator>
</transmission>
<transmission name="JointTrans4">
  <type>transmission_interface/SimpleTransmission</type>
  <joint name="joint4">
    <hardwareInterface>hardware_interface/EffortJointInterface</hardwareInterface>
  </joint>
  <actuator name="Actuator4">
    <hardwareInterface>hardware_interface/EffortJointInterface</hardwareInterface>
    <mechanicalReduction>1</mechanicalReduction>
  </actuator>
</transmission>
<transmission name="JointTrans5">
  <type>transmission_interface/SimpleTransmission</type>
  <joint name="joint5">
    <hardwareInterface>hardware_interface/EffortJointInterface</hardwareInterface>
  </joint>
  <actuator name="Actuator5">
    <hardwareInterface>hardware_interface/EffortJointInterface</hardwareInterface>
    <mechanicalReduction>1</mechanicalReduction>
  </actuator>
</transmission>
<transmission name="JointTrans6">
  <type>transmission_interface/SimpleTransmission</type>
  <joint name="joint6">
    <hardwareInterface>hardware_interface/EffortJointInterface</hardwareInterface>
  </joint>
  <actuator name="Actuator6">
    <hardwareInterface>hardware_interface/EffortJointInterface</hardwareInterface>
    <mechanicalReduction>1</mechanicalReduction>
  </actuator>
</transmission>

<joint name="FL_hip_joint" type="revolute">
  <origin xyz="0.292 0.08 0" />
  <parent link="base" />
  <child link="FL_hip" />
  <axis xyz="-1 0 0" />
  <dynamics damping="0.01" friction="0.03" />
  <limit lower="-0.523" upper="0.261" effort="50" velocity="20" />
</joint>
<link name="FL_hip">
  <inertial>
    <origin xyz="-0.00075689 -0.0089129 -5.0528E-05" />
    <mass value="1.5767" />
    <inertia ixx="0.00155112" ixy="6.1989E-06" ixz="2.8652E-06" iyy="0.00295295" iyz="3.7E-06" izz="0.005509864" />
  </inertial>
  <visual>
    <geometry>
      <mesh filename="package://x20Z1_description/meshes/visual/FL_Hip.dae" scale="1 1 1" />
    </geometry>
  </visual>
</link>

<joint name="FL_thigh_joint" type="revolute">
  <origin xyz="0 0.12325 0" />
  <parent link="FL_hip" />
  <child link="FL_thigh" />
  <axis xyz="0 -1 0" />
  <dynamics damping="0.01" friction="0.03" />
  <limit lower="-2.53" upper="0.35" effort="50" velocity="20" />
</joint>

<link name="FL_thigh">
  <inertial>
    <origin xyz="-0.0025263 -0.022118 -0.0292" />
    <mass value="3.0063" />
    <inertia ixx="0.0092851" ixy="4.2848E-05" ixz="-3.0429E-06" iyy="0.0120815" iyz="-6.8889E-05" izz="0.00449991" />
  </inertial>
  <visual>
    <geometry>
      <mesh filename="package://x20Z1_description/meshes/visual/L_Thigh.dae" scale="1 1 1" />
    </geometry>
  </visual>
  <collision>
    <origin xyz="-0.02 0 -0.13" />
    <geometry>
      <cylinder length="0.25" radius="0.04" />
    </geometry>
  </collision>
</link>

<joint name="FL_calf_joint" type="revolute">
  <origin xyz="0 0 -0.3" />
  <parent link="FL_thigh" />
  <child link="FL_calf" />
  <axis xyz="0 -1 0" />
  <dynamics damping="0.01" friction="0.03" />
  <limit lower="0.35" upper="2.53" effort="80" velocity="20" />
</joint>

<link name="FL_calf">
  <inertial>
    <origin xyz="0.0070425 1.3129E-06 -0.16459" />
    <mass value="0.60332" />
    <inertia ixx="0.00786321" ixy="8.0708E-08" ixz="0.00019488" iyy="0.008136445" iyz="-1.6129E-06" izz="0.00035109" />
  </inertial>
  <visual>
    <geometry>
      <mesh filename="package://x20Z1_description/meshes/visual/Shank.dae" scale="1 1 1" />
    </geometry>
  </visual>
  <collision>
    <origin xyz="0.00 0 -0.155" />
    <geometry>
      <!-- <sphere radius="0.036"/> -->
      <cylinder length="0.22" radius="0.025" />
    </geometry>
  </collision>
</link>

<joint name="FL_Ankle" type="fixed" dont_collapse="true">
  <origin xyz="0 0.002 -0.32" />
  <parent link="FL_calf" />
  <child link="FL_foot" />
</joint>

<link name="FL_foot">
  <inertial>
    <mass value="0.06" />
    <inertia ixx="1E-12" ixy="0" ixz="0" iyy="1E-12" iyz="0" izz="1E-12" />
  </inertial>
  <collision>
    <geometry>
      <sphere radius="0.025" />
    </geometry>
  </collision>
</link>

<transmission name="FL_hip_tran">
  <type>transmission_interface/SimpleTransmission</type>
  <joint name="FL_hip_joint">
    <hardwareInterface>hardware_interface/EffortJointInterface</hardwareInterface>
  </joint>
  <actuator name="FL_hip_motor">
    <hardwareInterface>hardware_interface/EffortJointInterface</hardwareInterface>
    <mechanicalReduction>1</mechanicalReduction>
  </actuator>
</transmission>
<transmission name="FL_thigh_tran">
  <type>transmission_interface/SimpleTransmission</type>
  <joint name="FL_thigh_joint">
    <hardwareInterface>hardware_interface/EffortJointInterface</hardwareInterface>
  </joint>
  <actuator name="FL_thigh_motor">
    <hardwareInterface>hardware_interface/EffortJointInterface</hardwareInterface>
    <mechanicalReduction>1</mechanicalReduction>
  </actuator>
</transmission>
<transmission name="FL_calf_tran">
  <type>transmission_interface/SimpleTransmission</type>
  <joint name="FL_calf_joint">
    <hardwareInterface>hardware_interface/EffortJointInterface</hardwareInterface>
  </joint>
  <actuator name="FL_calf_motor">
    <hardwareInterface>hardware_interface/EffortJointInterface</hardwareInterface>
    <mechanicalReduction>1</mechanicalReduction>
  </actuator>
</transmission>


<joint name="FR_hip_joint" type="revolute">
  <origin xyz="0.292 -0.08 0" />
  <parent link="base" />
  <child link="FR_hip" />
  <axis xyz="-1 0 0" />
  <dynamics damping="0.01" friction="0.03" />
  <limit lower="-0.523" upper="0.261" effort="50" velocity="20" />
</joint>

<link name="FR_hip">
  <inertial>
    <origin xyz="-0.00075689 0.0089129 5.0528E-05" />
    <mass value="1.5767" />
    <inertia ixx="0.00155112" ixy="-6.1989E-06" ixz="-2.8652E-06" iyy="0.00295295" iyz="3.7E-06" izz="0.005509864" />
  </inertial>
  <visual>
    <geometry>
      <mesh filename="package://x20Z1_description/meshes/visual/FR_Hip.dae" scale="1 1 1" />
    </geometry>
  </visual>
</link>

<joint name="FR_thigh_joint" type="revolute">
  <origin xyz="0 -0.12325 0" />
  <parent link="FR_hip" />
  <child link="FR_thigh" />
  <axis xyz="0 -1 0" />
  <dynamics damping="0.01" friction="0.03" />
  <limit lower="-2.53" upper="0.35" effort="50" velocity="20" />
</joint>

<link name="FR_thigh">
  <inertial>
    <origin xyz="-0.0025266 0.022119 -0.029194" />
    <mass value="3.0062" />
    <inertia ixx="0.0092851" ixy="-4.2781E-05" ixz="-3.0682E-06" iyy="0.0120815" iyz="6.8812E-05" izz="0.00449991" />
  </inertial>
  <visual>
    <geometry>
      <mesh filename="package://x20Z1_description/meshes/visual/R_Thigh.dae" scale="1 1 1" />
    </geometry>
  </visual>
  <collision>
    <origin xyz="-0.02 0 -0.13" />
    <geometry>
      <cylinder length="0.25" radius="0.04" />
    </geometry>
  </collision>
</link>

<joint name="FR_calf_joint" type="revolute">
  <origin xyz="0 0 -0.3" />
  <parent link="FR_thigh" />
  <child link="FR_calf" />
  <axis xyz="0 -1 0" />
  <dynamics damping="0.01" friction="0.03" />
  <limit lower="0.35" upper="2.53" effort="80" velocity="20" />
</joint>

<link name="FR_calf">
  <inertial>
    <origin xyz="0.0070425 1.3129E-06 -0.16459" />
    <mass value="0.60332" />
    <inertia ixx="0.00786321" ixy="8.0708E-08" ixz="0.00019488" iyy="0.008136445" iyz="-1.6129E-06" izz="0.00035109" />
  </inertial>
  <visual>
    <geometry>
      <mesh filename="package://x20Z1_description/meshes/visual/Shank.dae" scale="1 1 1" />
    </geometry>
  </visual>
  <collision>
    <origin xyz="0.00 0 -0.155" />
    <geometry>
      <!-- <sphere radius="0.036"/> -->
      <cylinder length="0.22" radius="0.025" />
    </geometry>
  </collision>
</link>

<joint name="FR_Ankle" type="fixed" dont_collapse="true">
  <origin xyz="0 -0.002 -0.32" />
  <parent link="FR_calf" />
  <child link="FR_foot" />
</joint>

<link name="FR_foot">
  <inertial>
    <mass value="0.06" />
    <inertia ixx="1E-12" ixy="0" ixz="0" iyy="1E-12" iyz="0" izz="1E-12" />
  </inertial>
  <collision>
    <geometry>
      <sphere radius="0.025" />
    </geometry>
  </collision>
</link>

<transmission name="FR_hip_tran">
  <type>transmission_interface/SimpleTransmission</type>
  <joint name="FR_hip_joint">
    <hardwareInterface>hardware_interface/EffortJointInterface</hardwareInterface>
  </joint>
  <actuator name="FR_hip_motor">
    <hardwareInterface>hardware_interface/EffortJointInterface</hardwareInterface>
    <mechanicalReduction>1</mechanicalReduction>
  </actuator>
</transmission>
<transmission name="FR_thigh_tran">
  <type>transmission_interface/SimpleTransmission</type>
  <joint name="FR_thigh_joint">
    <hardwareInterface>hardware_interface/EffortJointInterface</hardwareInterface>
  </joint>
  <actuator name="FR_thigh_motor">
    <hardwareInterface>hardware_interface/EffortJointInterface</hardwareInterface>
    <mechanicalReduction>1</mechanicalReduction>
  </actuator>
</transmission>
<transmission name="FR_calf_tran">
  <type>transmission_interface/SimpleTransmission</type>
  <joint name="FR_calf_joint">
    <hardwareInterface>hardware_interface/EffortJointInterface</hardwareInterface>
  </joint>
  <actuator name="FR_calf_motor">
    <hardwareInterface>hardware_interface/EffortJointInterface</hardwareInterface>
    <mechanicalReduction>1</mechanicalReduction>
  </actuator>
</transmission>

<joint name="RL_hip_joint" type="revolute">
  <origin xyz="-0.292 0.08 0" />
  <parent link="base" />
  <child link="RL_hip" />
  <axis xyz="-1 0 0" />
  <dynamics damping="0.01" friction="0.03" />
  <limit lower="-0.523" upper="0.261" effort="50" velocity="20" />
</joint>

<link name="RL_hip">
  <inertial>
    <origin xyz="0.00075689 -0.0089129 5.0528E-05" />
    <mass value="1.5767" />
    <inertia ixx="0.00155112" ixy="-6.1989E-06" ixz="2.8652E-06" iyy="0.00295295" iyz="-3.7E-06" izz="0.005509864" />
  </inertial>
  <visual>
    <geometry>
      <mesh filename="package://x20Z1_description/meshes/visual/HL_Hip.dae" scale="1 1 1" />
    </geometry>
  </visual>
</link>

<joint name="RL_thigh_joint" type="revolute">
  <origin xyz="0 0.12325 0" />
  <parent link="RL_hip" />
  <child link="RL_thigh" />
  <axis xyz="0 -1 0" />
  <dynamics damping="0.01" friction="0.03" />
  <limit lower="-2.53" upper="0.35" effort="50" velocity="20" />
</joint>

<link name="RL_thigh">
  <inertial>
    <origin xyz="-0.0025264 -0.022118 -0.0292" />
    <mass value="3.0063" />
    <inertia ixx="0.0092851" ixy="4.2848E-05" ixz="-3.0429E-06" iyy="0.0120815" iyz="-6.8889E-05" izz="0.00449991" />
  </inertial>
  <visual>
    <geometry>
      <mesh filename="package://x20Z1_description/meshes/visual/L_Thigh.dae" scale="1 1 1" />
    </geometry>
  </visual>
  <collision>
    <origin xyz="-0.02 0 -0.13" />
    <geometry>
      <cylinder length="0.25" radius="0.04" />
    </geometry>
  </collision>
</link>

<joint name="RL_calf_joint" type="revolute">
  <origin xyz="0 0 -0.3" />
  <parent link="RL_thigh" />
  <child link="RL_calf" />
  <axis xyz="0 -1 0" />
  <dynamics damping="0.01" friction="0.03" />
  <limit lower="0.35" upper="2.53" effort="80" velocity="20" />
</joint>

<link name="RL_calf">
  <inertial>
    <origin xyz="0.0070425 0 -0.16459" />
    <mass value="0.60332" />
    <inertia ixx="0.00786321" ixy="8.0708E-08" ixz="0.00019488" iyy="0.008136445" iyz="-1.6129E-06" izz="0.00035109" />
  </inertial>
  <visual>
    <geometry>
      <mesh filename="package://x20Z1_description/meshes/visual/Shank.dae" scale="1 1 1" />
    </geometry>
  </visual>
  <collision>
    <origin xyz="0.00 0 -0.155" />
    <geometry>
      <!-- <sphere radius="0.036"/> -->
      <cylinder length="0.22" radius="0.025" />
    </geometry>
  </collision>
</link>

<joint name="RL_Ankle" type="fixed" dont_collapse="true">
  <origin xyz="0 0.002 -0.32" />
  <parent link="RL_calf" />
  <child link="RL_foot" />
</joint>

<link name="RL_foot">
  <inertial>
    <mass value="0.06" />
    <inertia ixx="1E-12" ixy="0" ixz="0" iyy="1E-12" iyz="0" izz="1E-12" />
  </inertial>
  <collision>
    <geometry>
      <sphere radius="0.025" />
    </geometry>
  </collision>
</link>

<transmission name="RL_hip_tran">
  <type>transmission_interface/SimpleTransmission</type>
  <joint name="RL_hip_joint">
    <hardwareInterface>hardware_interface/EffortJointInterface</hardwareInterface>
  </joint>
  <actuator name="RL_hip_motor">
    <hardwareInterface>hardware_interface/EffortJointInterface</hardwareInterface>
    <mechanicalReduction>1</mechanicalReduction>
  </actuator>
</transmission>
<transmission name="RL_thigh_tran">
  <type>transmission_interface/SimpleTransmission</type>
  <joint name="RL_thigh_joint">
    <hardwareInterface>hardware_interface/EffortJointInterface</hardwareInterface>
  </joint>
  <actuator name="RL_thigh_motor">
    <hardwareInterface>hardware_interface/EffortJointInterface</hardwareInterface>
    <mechanicalReduction>1</mechanicalReduction>
  </actuator>
</transmission>
<transmission name="RL_calf_tran">
  <type>transmission_interface/SimpleTransmission</type>
  <joint name="RL_calf_joint">
    <hardwareInterface>hardware_interface/EffortJointInterface</hardwareInterface>
  </joint>
  <actuator name="RL_calf_motor">
    <hardwareInterface>hardware_interface/EffortJointInterface</hardwareInterface>
    <mechanicalReduction>1</mechanicalReduction>
  </actuator>
</transmission>

<joint name="RR_hip_joint" type="revolute">
  <origin xyz="-0.292 -0.08 0" />
  <parent link="base" />
  <child link="RR_hip" />
  <axis xyz="-1 0 0" />
  <dynamics damping="0.01" friction="0.03" />
  <limit lower="-0.523" upper="0.261" effort="50" velocity="20" />
</joint>

<link name="RR_hip">
  <inertial>
    <origin xyz="0.00075689 0.0089129 -5.0528E-05" />
    <mass value="1.5767" />
    <inertia ixx="0.00155112" ixy="6.1989E-06" ixz="-2.8652E-06" iyy="0.00295295" iyz="-3.7E-06" izz="0.005509864" />
  </inertial>
  <visual>
    <geometry>
      <mesh filename="package://x20Z1_description/meshes/visual/HR_Hip.dae" scale="1 1 1" />
    </geometry>
  </visual>
</link>

<joint name="RR_thigh_joint" type="revolute">
  <origin xyz="0 -0.12325 0" />
  <parent link="RR_hip" />
  <child link="RR_thigh" />
  <axis xyz="0 -1 0" />
  <dynamics damping="0.01" friction="0.03" />
  <limit lower="-2.53" upper="0.35" effort="50" velocity="20" />
</joint>

<link name="RR_thigh">
  <inertial>
    <origin xyz="-0.0025266 0.022119 -0.029194" />
    <mass value="3.0062" />
    <inertia ixx="0.0092851" ixy="-4.2781E-05" ixz="-3.0688E-06" iyy="0.0120815" iyz="6.8812E-05" izz="0.00449991" />
  </inertial>
  <visual>
    <geometry>
      <mesh filename="package://x20Z1_description/meshes/visual/R_Thigh.dae" scale="1 1 1" />
    </geometry>
  </visual>
  <collision>
    <origin xyz="-0.02 0 -0.13" />
    <geometry>
      <cylinder length="0.25" radius="0.04" />
    </geometry>
  </collision>
</link>

<joint name="RR_calf_joint" type="revolute">
  <origin xyz="0 0 -0.3" />
  <parent link="RR_thigh" />
  <child link="RR_calf" />
  <axis xyz="0 -1 0" />
  <dynamics damping="0.01" friction="0.03" />
  <limit lower="0.35" upper="2.53" effort="80" velocity="20" />
</joint>

<link name="RR_calf">
  <inertial>
    <origin xyz="0.0070425 0.0 -0.16459" />
    <mass value="0.60332" />
    <inertia ixx="0.00786321" ixy="8.0708E-08" ixz="0.00019488" iyy="0.008136445" iyz="-1.6129E-06" izz="0.00035109" />
  </inertial>
  <visual>
    <geometry>
      <mesh filename="package://x20Z1_description/meshes/visual/Shank.dae" scale="1 1 1" />
    </geometry>
  </visual>
  <collision>
    <origin xyz="0.00 0 -0.155" />
    <geometry>
      <!-- <sphere radius="0.036"/> -->
      <cylinder length="0.22" radius="0.025" />
    </geometry>
  </collision>
</link>

<joint name="HR_Ankle" type="fixed" dont_collapse="true">
  <origin xyz="0 -0.002 -0.32" />
  <parent link="RR_calf" />
  <child link="RR_foot" />
</joint>

<link name="RR_foot">
  <inertial>
    <mass value="0.06" />
    <inertia ixx="1E-12" ixy="0" ixz="0" iyy="1E-12" iyz="0" izz="1E-12" />
  </inertial>
  <collision>
    <geometry>
      <sphere radius="0.025" />
    </geometry>
  </collision>
</link>

<transmission name="RR_hip_tran">
  <type>transmission_interface/SimpleTransmission</type>
  <joint name="RR_hip_joint">
    <hardwareInterface>hardware_interface/EffortJointInterface</hardwareInterface>
  </joint>
  <actuator name="RR_hip_motor">
    <hardwareInterface>hardware_interface/EffortJointInterface</hardwareInterface>
    <mechanicalReduction>1</mechanicalReduction>
  </actuator>
</transmission>
<transmission name="RR_thigh_tran">
  <type>transmission_interface/SimpleTransmission</type>
  <joint name="RR_thigh_joint">
    <hardwareInterface>hardware_interface/EffortJointInterface</hardwareInterface>
  </joint>
  <actuator name="RR_thigh_motor">
    <hardwareInterface>hardware_interface/EffortJointInterface</hardwareInterface>
    <mechanicalReduction>1</mechanicalReduction>
  </actuator>
</transmission>
<transmission name="RR_calf_tran">
  <type>transmission_interface/SimpleTransmission</type>
  <joint name="RR_calf_joint">
    <hardwareInterface>hardware_interface/EffortJointInterface</hardwareInterface>
  </joint>
  <actuator name="RR_calf_motor">
    <hardwareInterface>hardware_interface/EffortJointInterface</hardwareInterface>
    <mechanicalReduction>1</mechanicalReduction>
  </actuator>
</transmission>

</robot>
